2017-01-26 22:42:36,647 p=3142 u=vagrant |  localhost | SUCCESS => {
    "changed": false, 
    "ping": "pong"
}
2017-01-26 22:43:49,696 p=3221 u=vagrant |  localhost | FAILED! => {
    "changed": false, 
    "failed": true, 
    "module_stderr": "Shared connection to localhost closed.\r\n", 
    "module_stdout": "Traceback (most recent call last):\r\n  File \"/tmp/ansible_B9S4I7/ansible_module_file.py\", line 451, in <module>\r\n    main()\r\n  File \"/tmp/ansible_B9S4I7/ansible_module_file.py\", line 422, in main\r\n    open(b_path, 'wb').close()\r\nIOError: [Errno 2] そのようなファイルやディレクトリはありません: '/home/ansible/test.txt'\r\n", 
    "msg": "MODULE FAILURE"
}
2017-01-26 22:44:33,509 p=3299 u=vagrant |  localhost | FAILED! => {
    "changed": false, 
    "failed": true, 
    "module_stderr": "Shared connection to localhost closed.\r\n", 
    "module_stdout": "Traceback (most recent call last):\r\n  File \"/tmp/ansible_jVx0jN/ansible_module_file.py\", line 451, in <module>\r\n    main()\r\n  File \"/tmp/ansible_jVx0jN/ansible_module_file.py\", line 422, in main\r\n    open(b_path, 'wb').close()\r\nIOError: [Errno 2] そのようなファイルやディレクトリはありません: '/home/ansible/test.txt'\r\n", 
    "msg": "MODULE FAILURE"
}
2017-01-26 22:46:07,871 p=3380 u=vagrant |  localhost | FAILED! => {
    "changed": false, 
    "failed": true, 
    "module_stderr": "Shared connection to localhost closed.\r\n", 
    "module_stdout": "Traceback (most recent call last):\r\n  File \"/tmp/ansible_0rnuYg/ansible_module_file.py\", line 451, in <module>\r\n    main()\r\n  File \"/tmp/ansible_0rnuYg/ansible_module_file.py\", line 422, in main\r\n    open(b_path, 'wb').close()\r\nIOError: [Errno 13] 許可がありません: '/home/ansible/test.txt'\r\n", 
    "msg": "MODULE FAILURE"
}
2017-01-26 22:46:17,367 p=3460 u=vagrant |   [WARNING]: Host file not found: inventory/test01_inventory.ini

2017-01-26 22:46:17,370 p=3460 u=vagrant |   [WARNING]: provided hosts list is empty, only localhost is available

2017-01-26 22:46:17,370 p=3460 u=vagrant |   [WARNING]: No hosts matched, nothing to do

2017-01-26 22:46:39,032 p=3469 u=vagrant |  localhost | FAILED! => {
    "changed": false, 
    "failed": true, 
    "module_stderr": "Shared connection to localhost closed.\r\n", 
    "module_stdout": "Traceback (most recent call last):\r\n  File \"/tmp/ansible_4RQAAp/ansible_module_file.py\", line 451, in <module>\r\n    main()\r\n  File \"/tmp/ansible_4RQAAp/ansible_module_file.py\", line 422, in main\r\n    open(b_path, 'wb').close()\r\nIOError: [Errno 13] 許可がありません: '/home/ansible/test.txt'\r\n", 
    "msg": "MODULE FAILURE"
}
2017-01-26 22:57:07,474 p=3565 u=vagrant |  PLAY [test_servers] ************************************************************
2017-01-26 22:57:07,511 p=3565 u=vagrant |  TASK [setup] *******************************************************************
2017-01-26 22:57:17,854 p=3565 u=vagrant |  fatal: [192.168.0.101]: UNREACHABLE! => {"changed": false, "msg": "Failed to connect to the host via ssh: ssh: connect to host 192.168.0.101 port 22: Connection timed out\r\n", "unreachable": true}
2017-01-26 22:57:17,968 p=3565 u=vagrant |  fatal: [192.168.0.102]: UNREACHABLE! => {"changed": false, "msg": "Failed to connect to the host via ssh: ssh: connect to host 192.168.0.102 port 22: Connection timed out\r\n", "unreachable": true}
2017-01-26 22:57:17,971 p=3565 u=vagrant |  	to retry, use: --limit @/home/vagrant/PATH_TO/effective_ansible/sec2/test_playbook.retry

2017-01-26 22:57:17,971 p=3565 u=vagrant |  PLAY RECAP *********************************************************************
2017-01-26 22:57:17,971 p=3565 u=vagrant |  192.168.0.101              : ok=0    changed=0    unreachable=1    failed=0   
2017-01-26 22:57:17,971 p=3565 u=vagrant |  192.168.0.102              : ok=0    changed=0    unreachable=1    failed=0   
2017-01-27 10:55:50,823 p=3512 u=vagrant |  ERROR! the playbook: ./sec2/test_playbook.yml could not be found
2017-01-27 10:56:04,452 p=3517 u=vagrant |  ERROR! the playbook: ./sec2/test_playbook.yml could not be found
2017-01-27 10:56:08,838 p=3522 u=vagrant |  PLAY [test_servers] ************************************************************
2017-01-27 10:56:08,967 p=3522 u=vagrant |  TASK [setup] *******************************************************************
2017-01-27 10:56:09,709 p=3522 u=vagrant |  fatal: [192.168.56.102]: UNREACHABLE! => {"changed": false, "msg": "Failed to connect to the host via ssh: Warning: Permanently added '192.168.56.102' (ECDSA) to the list of known hosts.\r\nPermission denied (publickey,gssapi-keyex,gssapi-with-mic,password).\r\n", "unreachable": true}
2017-01-27 10:56:12,082 p=3522 u=vagrant |  ok: [192.168.56.101]
2017-01-27 10:56:12,086 p=3522 u=vagrant |  TASK [create directory] ********************************************************
2017-01-27 10:56:12,634 p=3522 u=vagrant |  fatal: [192.168.56.101]: FAILED! => {"changed": false, "failed": true, "msg": "There was an issue creating /home/ansible/tmp as requested: [Errno 13] 許可がありません: '/home/ansible/tmp'", "path": "/home/ansible/tmp", "state": "absent"}
2017-01-27 10:56:12,637 p=3522 u=vagrant |  	to retry, use: --limit @/home/vagrant/PATH_TO/effective_ansible/sec2/test_playbook.retry

2017-01-27 10:56:12,638 p=3522 u=vagrant |  PLAY RECAP *********************************************************************
2017-01-27 10:56:12,638 p=3522 u=vagrant |  192.168.56.101             : ok=1    changed=0    unreachable=0    failed=1   
2017-01-27 10:56:12,638 p=3522 u=vagrant |  192.168.56.102             : ok=0    changed=0    unreachable=1    failed=0   
2017-01-27 21:56:20,137 p=5157 u=vagrant |  PLAY [test_servers] ************************************************************
2017-01-27 21:56:20,172 p=5157 u=vagrant |  TASK [setup] *******************************************************************
2017-01-27 21:56:20,623 p=5157 u=vagrant |  fatal: [192.168.56.102]: UNREACHABLE! => {"changed": false, "msg": "Failed to connect to the host via ssh: Permission denied (publickey,gssapi-keyex,gssapi-with-mic,password).\r\n", "unreachable": true}
2017-01-27 21:56:22,039 p=5157 u=vagrant |  ok: [192.168.56.101]
2017-01-27 21:56:22,043 p=5157 u=vagrant |  TASK [create directory] ********************************************************
2017-01-27 21:56:22,526 p=5157 u=vagrant |  fatal: [192.168.56.101]: FAILED! => {"changed": false, "failed": true, "msg": "There was an issue creating /home/ansible/tmp as requested: [Errno 13] 許可がありません: '/home/ansible/tmp'", "path": "/home/ansible/tmp", "state": "absent"}
2017-01-27 21:56:22,530 p=5157 u=vagrant |  	to retry, use: --limit @/home/vagrant/PATH_TO/effective_ansible/sec2/test_playbook.retry

2017-01-27 21:56:22,530 p=5157 u=vagrant |  PLAY RECAP *********************************************************************
2017-01-27 21:56:22,530 p=5157 u=vagrant |  192.168.56.101             : ok=1    changed=0    unreachable=0    failed=1   
2017-01-27 21:56:22,531 p=5157 u=vagrant |  192.168.56.102             : ok=0    changed=0    unreachable=1    failed=0   
2017-01-27 21:59:14,288 p=5333 u=vagrant |  ERROR! the playbook: ./sec2/test_playbook.yml could not be found
2017-01-27 21:59:37,106 p=5339 u=vagrant |  PLAY [test_servers] ************************************************************
2017-01-27 21:59:37,142 p=5339 u=vagrant |  TASK [setup] *******************************************************************
2017-01-27 21:59:37,599 p=5339 u=vagrant |  fatal: [192.168.56.102]: UNREACHABLE! => {"changed": false, "msg": "Failed to connect to the host via ssh: Permission denied (publickey,gssapi-keyex,gssapi-with-mic,password).\r\n", "unreachable": true}
2017-01-27 21:59:39,121 p=5339 u=vagrant |  ok: [192.168.56.101]
2017-01-27 21:59:39,123 p=5339 u=vagrant |  TASK [create directory] ********************************************************
2017-01-27 21:59:39,588 p=5339 u=vagrant |  fatal: [192.168.56.101]: FAILED! => {"changed": false, "failed": true, "gid": 0, "group": "root", "mode": "0755", "msg": "chown failed: failed to look up user ansible", "owner": "root", "path": "/home/ansible/tmp", "size": 6, "state": "directory", "uid": 0}
2017-01-27 21:59:39,591 p=5339 u=vagrant |  	to retry, use: --limit @/home/vagrant/PATH_TO/effective_ansible/sec2/test_playbook.retry

2017-01-27 21:59:39,591 p=5339 u=vagrant |  PLAY RECAP *********************************************************************
2017-01-27 21:59:39,591 p=5339 u=vagrant |  192.168.56.101             : ok=1    changed=0    unreachable=0    failed=1   
2017-01-27 21:59:39,591 p=5339 u=vagrant |  192.168.56.102             : ok=0    changed=0    unreachable=1    failed=0   
2017-01-27 22:08:48,417 p=5607 u=vagrant |  ERROR! the playbook: ./sec2/test_playbook.yml could not be found
2017-01-27 22:09:04,962 p=5614 u=vagrant |  PLAY [test_servers] ************************************************************
2017-01-27 22:09:04,998 p=5614 u=vagrant |  TASK [setup] *******************************************************************
2017-01-27 22:09:05,451 p=5614 u=vagrant |  fatal: [192.168.56.102]: UNREACHABLE! => {"changed": false, "msg": "Failed to connect to the host via ssh: Permission denied (publickey,gssapi-keyex,gssapi-with-mic,password).\r\n", "unreachable": true}
2017-01-27 22:09:06,828 p=5614 u=vagrant |  ok: [192.168.56.101]
2017-01-27 22:09:06,831 p=5614 u=vagrant |  TASK [create directory] ********************************************************
2017-01-27 22:09:07,301 p=5614 u=vagrant |  fatal: [192.168.56.101]: FAILED! => {"changed": false, "failed": true, "gid": 0, "group": "root", "mode": "0755", "msg": "chown failed: failed to look up user ansible", "owner": "root", "path": "/home/ansible/tmp", "size": 6, "state": "directory", "uid": 0}
2017-01-27 22:09:07,304 p=5614 u=vagrant |  	to retry, use: --limit @/home/vagrant/PATH_TO/effective_ansible/sec2/test_playbook.retry

2017-01-27 22:09:07,304 p=5614 u=vagrant |  PLAY RECAP *********************************************************************
2017-01-27 22:09:07,305 p=5614 u=vagrant |  192.168.56.101             : ok=1    changed=0    unreachable=0    failed=1   
2017-01-27 22:09:07,305 p=5614 u=vagrant |  192.168.56.102             : ok=0    changed=0    unreachable=1    failed=0   
2017-01-27 22:11:52,750 p=5787 u=vagrant |  ERROR! the playbook: ./sec2/test_playbook.yml could not be found
2017-01-27 22:11:57,929 p=5792 u=vagrant |  ERROR! Syntax Error while loading YAML.


The error appears to have been in '/home/vagrant/PATH_TO/effective_ansible/sec2/test_playbook.yml': line 5, column 3, but may
be elsewhere in the file depending on the exact syntax problem.

The offending line appears to be:

  become: true
  - name: create directory
  ^ here

2017-01-27 22:15:19,488 p=5803 u=vagrant |  PLAY [test_servers] ************************************************************
2017-01-27 22:15:19,526 p=5803 u=vagrant |  TASK [setup] *******************************************************************
2017-01-27 22:15:19,960 p=5803 u=vagrant |  fatal: [192.168.56.102]: UNREACHABLE! => {"changed": false, "msg": "Failed to connect to the host via ssh: Permission denied (publickey,gssapi-keyex,gssapi-with-mic,password).\r\n", "unreachable": true}
2017-01-27 22:15:21,423 p=5803 u=vagrant |  ok: [192.168.56.101]
2017-01-27 22:15:21,426 p=5803 u=vagrant |  TASK [create directory] ********************************************************
2017-01-27 22:15:21,900 p=5803 u=vagrant |  fatal: [192.168.56.101]: FAILED! => {"changed": false, "failed": true, "gid": 0, "group": "root", "mode": "0755", "msg": "chown failed: failed to look up user ansible", "owner": "root", "path": "/home/ansible/tmp", "size": 6, "state": "directory", "uid": 0}
2017-01-27 22:15:21,902 p=5803 u=vagrant |  	to retry, use: --limit @/home/vagrant/PATH_TO/effective_ansible/sec2/test_playbook.retry

2017-01-27 22:15:21,902 p=5803 u=vagrant |  PLAY RECAP *********************************************************************
2017-01-27 22:15:21,902 p=5803 u=vagrant |  192.168.56.101             : ok=1    changed=0    unreachable=0    failed=1   
2017-01-27 22:15:21,903 p=5803 u=vagrant |  192.168.56.102             : ok=0    changed=0    unreachable=1    failed=0   
